<?xml version="1.0" ?>
<!-- Generated using onshape-to-robot -->
<!-- Onshape https://cad.onshape.com/documents/d7eef6374aced10980d655e0/w/a95c1ea2fcec3b2e30db9b5b/e/416f6c94a31540a06b47b379 -->
<mujoco model="morris_6dof_mujoco">
  <compiler angle="radian" meshdir="assets" autolimits="true"/>
  <default>
    <default class="morris_6dof_mujoco">
      <joint frictionloss="0.1" armature="0.005"/>
      <position kp="50" dampratio="1"/>
      <default class="visual">
        <geom type="mesh" contype="0" conaffinity="0" group="2"/>
      </default>
      <default class="collision">
        <geom group="3"/>
      </default>
    </default>
  </default>
  <worldbody>
    <!-- Link a_v3_base -->
    <body name="a_v3_base" pos="0 0 0" quat="1 0 0 0" childclass="morris_6dof_mujoco">
      <inertial pos="-0.00597698 0.00971512 0.011824" mass="0.219524" fullinertia="0.000386732 0.000335538 0.00065635 5.87702e-05 -4.6693e-06 -1.7287e-08"/>
      <!-- Part ph_pan_head_screw_m3x0_50_x_6__b32648e3119e9bfb9d9baf1e22451401 -->
      <geom type="mesh" class="visual" pos="-0.0501029 0.078258 0.013175" quat="0.707107 0 0 0.707107" mesh="ph_pan_head_screw_m3x0_50_x_6__b32648e3119e9bfb9d9baf1e22451401" material="ph_pan_head_screw_m3x0_50_x_6__b32648e3119e9bfb9d9baf1e22451401_material"/>
      <geom type="mesh" class="collision" pos="-0.0501029 0.078258 0.013175" quat="0.707107 0 0 0.707107" mesh="ph_pan_head_screw_m3x0_50_x_6__b32648e3119e9bfb9d9baf1e22451401" material="ph_pan_head_screw_m3x0_50_x_6__b32648e3119e9bfb9d9baf1e22451401_material"/>
      <!-- Part base -->
      <geom type="mesh" class="visual" pos="0.000397123 -0.000741956 0.00317497" quat="1 -0 -0 0" mesh="base" material="base_material"/>
      <geom type="mesh" class="collision" pos="0.000397123 -0.000741956 0.00317497" quat="1 -0 -0 0" mesh="base" material="base_material"/>
      <!-- Part pca9685_generic -->
      <geom type="mesh" class="visual" pos="0.00639712 -0.036742 0.00837497" quat="1 -0 -0 0" mesh="pca9685_generic" material="pca9685_generic_material"/>
      <geom type="mesh" class="collision" pos="0.00639712 -0.036742 0.00837497" quat="1 -0 -0 0" mesh="pca9685_generic" material="pca9685_generic_material"/>
      <!-- Part ph_pan_head_screw_m3x0_50_x_6__b32648e3119e9bfb9d9baf1e22451401_2 -->
      <geom type="mesh" class="visual" pos="-0.0271029 0.032258 0.013175" quat="0.707107 0 0 0.707107" mesh="ph_pan_head_screw_m3x0_50_x_6__b32648e3119e9bfb9d9baf1e22451401" material="ph_pan_head_screw_m3x0_50_x_6__b32648e3119e9bfb9d9baf1e22451401_material"/>
      <geom type="mesh" class="collision" pos="-0.0271029 0.032258 0.013175" quat="0.707107 0 0 0.707107" mesh="ph_pan_head_screw_m3x0_50_x_6__b32648e3119e9bfb9d9baf1e22451401" material="ph_pan_head_screw_m3x0_50_x_6__b32648e3119e9bfb9d9baf1e22451401_material"/>
      <!-- Part ph_pan_head_screw_m3x0_50_x_6__b32648e3119e9bfb9d9baf1e22451401_3 -->
      <geom type="mesh" class="visual" pos="-0.0501029 0.032258 0.013175" quat="0.707107 0 0 0.707107" mesh="ph_pan_head_screw_m3x0_50_x_6__b32648e3119e9bfb9d9baf1e22451401" material="ph_pan_head_screw_m3x0_50_x_6__b32648e3119e9bfb9d9baf1e22451401_material"/>
      <geom type="mesh" class="collision" pos="-0.0501029 0.032258 0.013175" quat="0.707107 0 0 0.707107" mesh="ph_pan_head_screw_m3x0_50_x_6__b32648e3119e9bfb9d9baf1e22451401" material="ph_pan_head_screw_m3x0_50_x_6__b32648e3119e9bfb9d9baf1e22451401_material"/>
      <!-- Part ph_pan_head_screw_m3x0_50_x_6__b32648e3119e9bfb9d9baf1e22451401_4 -->
      <geom type="mesh" class="visual" pos="-0.0271029 0.078258 0.013175" quat="0.707107 0 0 0.707107" mesh="ph_pan_head_screw_m3x0_50_x_6__b32648e3119e9bfb9d9baf1e22451401" material="ph_pan_head_screw_m3x0_50_x_6__b32648e3119e9bfb9d9baf1e22451401_material"/>
      <geom type="mesh" class="collision" pos="-0.0271029 0.078258 0.013175" quat="0.707107 0 0 0.707107" mesh="ph_pan_head_screw_m3x0_50_x_6__b32648e3119e9bfb9d9baf1e22451401" material="ph_pan_head_screw_m3x0_50_x_6__b32648e3119e9bfb9d9baf1e22451401_material"/>
      <!-- Part pinheader_1x15_p254mm_vertical -->
      <geom type="mesh" class="visual" pos="-0.0387099 0.0554501 0.010725" quat="0 0.707107 0.707107 0" mesh="pinheader_1x15_p254mm_vertical" material="pinheader_1x15_p254mm_vertical_material"/>
      <geom type="mesh" class="collision" pos="-0.0387099 0.0554501 0.010725" quat="0 0.707107 0.707107 0" mesh="pinheader_1x15_p254mm_vertical" material="pinheader_1x15_p254mm_vertical_material"/>
      <!-- Part lqfp_52_14x14mm_p1mm -->
      <geom type="mesh" class="visual" pos="-0.0387079 0.0584501 0.010825" quat="0 0.707107 0.707107 0" mesh="lqfp_52_14x14mm_p1mm" material="lqfp_52_14x14mm_p1mm_material"/>
      <geom type="mesh" class="collision" pos="-0.0387079 0.0584501 0.010825" quat="0 0.707107 0.707107 0" mesh="lqfp_52_14x14mm_p1mm" material="lqfp_52_14x14mm_p1mm_material"/>
      <!-- Part usb_micro_b_molex_47346_0001 -->
      <geom type="mesh" class="visual" pos="-0.0387079 0.0554501 0.0108326" quat="0 0.707107 0.707107 0" mesh="usb_micro_b_molex_47346_0001" material="usb_micro_b_molex_47346_0001_material"/>
      <geom type="mesh" class="collision" pos="-0.0387079 0.0554501 0.0108326" quat="0 0.707107 0.707107 0" mesh="usb_micro_b_molex_47346_0001" material="usb_micro_b_molex_47346_0001_material"/>
      <!-- Part esp32_30pin_pcb -->
      <geom type="mesh" class="visual" pos="-0.0387079 0.0554501 0.010775" quat="0 0.707107 0.707107 0" mesh="esp32_30pin_pcb" material="esp32_30pin_pcb_material"/>
      <geom type="mesh" class="collision" pos="-0.0387079 0.0554501 0.010775" quat="0 0.707107 0.707107 0" mesh="esp32_30pin_pcb" material="esp32_30pin_pcb_material"/>
      <!-- Part lqfp_32_5x5mm_p05mm -->
      <geom type="mesh" class="visual" pos="-0.0387079 0.0504501 0.010925" quat="0 0.707107 0.707107 0" mesh="lqfp_32_5x5mm_p05mm" material="lqfp_32_5x5mm_p05mm_material"/>
      <geom type="mesh" class="collision" pos="-0.0387079 0.0504501 0.010925" quat="0 0.707107 0.707107 0" mesh="lqfp_32_5x5mm_p05mm" material="lqfp_32_5x5mm_p05mm_material"/>
      <!-- Part pinheader_1x15_p254mm_vertical_1 -->
      <geom type="mesh" class="visual" pos="-0.0387059 0.0554501 0.010725" quat="0 0.707107 0.707107 0" mesh="pinheader_1x15_p254mm_vertical_1" material="pinheader_1x15_p254mm_vertical_1_material"/>
      <geom type="mesh" class="collision" pos="-0.0387059 0.0554501 0.010725" quat="0 0.707107 0.707107 0" mesh="pinheader_1x15_p254mm_vertical_1" material="pinheader_1x15_p254mm_vertical_1_material"/>
      <!-- Part mg996r -->
      <geom type="mesh" class="visual" pos="0.000397123 -0.0110911 0.00118093" quat="0.707107 -0 -0 0.707107" mesh="mg996r" material="mg996r_material"/>
      <geom type="mesh" class="collision" pos="0.000397123 -0.0110911 0.00118093" quat="0.707107 -0 -0 0.707107" mesh="mg996r" material="mg996r_material"/>
      <!-- Part attach -->
      <geom type="mesh" class="visual" pos="0.000397123 -0.0110911 0.00168093" quat="0.707107 -0 -0 0.707107" mesh="attach" material="attach_material"/>
      <geom type="mesh" class="collision" pos="0.000397123 -0.0110911 0.00168093" quat="0.707107 -0 -0 0.707107" mesh="attach" material="attach_material"/>
      <!-- Link a_v3_link1b -->
      <body name="a_v3_link1b" pos="0.000397123 -0.000741956 0.045175" quat="0 0.703968 0.710232 -0">
        <!-- Joint from a_v3_base to a_v3_link1b -->
        <joint axis="0 0 1" name="joint1" type="hinge" range="-1.561937945537009 1.579654708052784"/>
        <inertial pos="-7.6e-11 -0.0368364 -0.0206386" mass="0.0269787" fullinertia="9.94957e-06 1.33304e-05 1.14838e-05 0 -0 2.72858e-07"/>
        <!-- Part ph_pan_head_screw_m3x0_50_x_6__b32648e3119e9bfb9d9baf1e22451401_5 -->
        <geom type="mesh" class="visual" pos="0 0 -0.0064" quat="0 -0.707107 -0.707107 -0" mesh="ph_pan_head_screw_m3x0_50_x_6__b32648e3119e9bfb9d9baf1e22451401" material="ph_pan_head_screw_m3x0_50_x_6__b32648e3119e9bfb9d9baf1e22451401_material"/>
        <geom type="mesh" class="collision" pos="0 0 -0.0064" quat="0 -0.707107 -0.707107 -0" mesh="ph_pan_head_screw_m3x0_50_x_6__b32648e3119e9bfb9d9baf1e22451401" material="ph_pan_head_screw_m3x0_50_x_6__b32648e3119e9bfb9d9baf1e22451401_material"/>
        <!-- Part link1_1 -->
        <geom type="mesh" class="visual" pos="0 -0.03 -0.04" quat="0 0.707107 0.707107 0" mesh="link1_1" material="link1_1_material"/>
        <geom type="mesh" class="collision" pos="0 -0.03 -0.04" quat="0 0.707107 0.707107 0" mesh="link1_1" material="link1_1_material"/>
        <!-- Part ph_pan_head_screw_m3x0_50_x_6__b32648e3119e9bfb9d9baf1e22451401_6 -->
        <geom type="mesh" class="visual" pos="0 -0.0364 -0.04" quat="0.707107 0.707107 -0 -0" mesh="ph_pan_head_screw_m3x0_50_x_6__b32648e3119e9bfb9d9baf1e22451401" material="ph_pan_head_screw_m3x0_50_x_6__b32648e3119e9bfb9d9baf1e22451401_material"/>
        <geom type="mesh" class="collision" pos="0 -0.0364 -0.04" quat="0.707107 0.707107 -0 -0" mesh="ph_pan_head_screw_m3x0_50_x_6__b32648e3119e9bfb9d9baf1e22451401" material="ph_pan_head_screw_m3x0_50_x_6__b32648e3119e9bfb9d9baf1e22451401_material"/>
        <!-- Part ph_pan_head_screw_m3x0_50_x_10__f9471002c7d2be787504e53f034b0545 -->
        <geom type="mesh" class="visual" pos="0.015 -0.055 -0.0104" quat="0 0.707107 0.707107 0" mesh="ph_pan_head_screw_m3x0_50_x_10__f9471002c7d2be787504e53f034b0545" material="ph_pan_head_screw_m3x0_50_x_10__f9471002c7d2be787504e53f034b0545_material"/>
        <geom type="mesh" class="collision" pos="0.015 -0.055 -0.0104" quat="0 0.707107 0.707107 0" mesh="ph_pan_head_screw_m3x0_50_x_10__f9471002c7d2be787504e53f034b0545" material="ph_pan_head_screw_m3x0_50_x_10__f9471002c7d2be787504e53f034b0545_material"/>
        <!-- Part ph_pan_head_screw_m3x0_50_x_10__f9471002c7d2be787504e53f034b0545_2 -->
        <geom type="mesh" class="visual" pos="-0.015 -0.039 -0.0104" quat="0 0.707107 0.707107 0" mesh="ph_pan_head_screw_m3x0_50_x_10__f9471002c7d2be787504e53f034b0545" material="ph_pan_head_screw_m3x0_50_x_10__f9471002c7d2be787504e53f034b0545_material"/>
        <geom type="mesh" class="collision" pos="-0.015 -0.039 -0.0104" quat="0 0.707107 0.707107 0" mesh="ph_pan_head_screw_m3x0_50_x_10__f9471002c7d2be787504e53f034b0545" material="ph_pan_head_screw_m3x0_50_x_10__f9471002c7d2be787504e53f034b0545_material"/>
        <!-- Part mg996r_straight -->
        <geom type="mesh" class="visual" pos="-0 -0.03235 -0.04" quat="0.707107 -0 -0.707107 0" mesh="mg996r_straight" material="mg996r_straight_material"/>
        <geom type="mesh" class="collision" pos="-0 -0.03235 -0.04" quat="0.707107 -0 -0.707107 0" mesh="mg996r_straight" material="mg996r_straight_material"/>
        <!-- Part ph_pan_head_screw_m3x0_50_x_10__f9471002c7d2be787504e53f034b0545_3 -->
        <geom type="mesh" class="visual" pos="0.015 -0.039 -0.0104" quat="0 0.707107 0.707107 0" mesh="ph_pan_head_screw_m3x0_50_x_10__f9471002c7d2be787504e53f034b0545" material="ph_pan_head_screw_m3x0_50_x_10__f9471002c7d2be787504e53f034b0545_material"/>
        <geom type="mesh" class="collision" pos="0.015 -0.039 -0.0104" quat="0 0.707107 0.707107 0" mesh="ph_pan_head_screw_m3x0_50_x_10__f9471002c7d2be787504e53f034b0545" material="ph_pan_head_screw_m3x0_50_x_10__f9471002c7d2be787504e53f034b0545_material"/>
        <!-- Part mg996r_straight_2 -->
        <geom type="mesh" class="visual" pos="-0 -0 -0.00235" quat="0.707107 0.707107 0 0" mesh="mg996r_straight" material="mg996r_straight_material"/>
        <geom type="mesh" class="collision" pos="-0 -0 -0.00235" quat="0.707107 0.707107 0 0" mesh="mg996r_straight" material="mg996r_straight_material"/>
        <!-- Part ph_pan_head_screw_m3x0_50_x_10__f9471002c7d2be787504e53f034b0545_4 -->
        <geom type="mesh" class="visual" pos="-0.015 -0.055 -0.0104" quat="0 0.707107 0.707107 0" mesh="ph_pan_head_screw_m3x0_50_x_10__f9471002c7d2be787504e53f034b0545" material="ph_pan_head_screw_m3x0_50_x_10__f9471002c7d2be787504e53f034b0545_material"/>
        <geom type="mesh" class="collision" pos="-0.015 -0.055 -0.0104" quat="0 0.707107 0.707107 0" mesh="ph_pan_head_screw_m3x0_50_x_10__f9471002c7d2be787504e53f034b0545" material="ph_pan_head_screw_m3x0_50_x_10__f9471002c7d2be787504e53f034b0545_material"/>
        <!-- Part link1_1b -->
        <geom type="mesh" class="visual" pos="0 -0 0" quat="0 -0.707107 -0.707107 -0" mesh="link1_1b" material="link1_1b_material"/>
        <geom type="mesh" class="collision" pos="0 -0 0" quat="0 -0.707107 -0.707107 -0" mesh="link1_1b" material="link1_1b_material"/>
        <!-- Link a_v3_link2b -->
        <body name="a_v3_link2b" pos="-0 -0.03 -0.04" quat="0.707107 0.707107 0 -0">
          <!-- Joint from a_v3_link1b to a_v3_link2b -->
          <joint axis="0 0 1" name="joint2" type="hinge" range="-3.141592653589301 4.920508445138694e-13"/>
          <inertial pos="0.0500006 -0.0156806 -0.0240829" mass="0.120681" fullinertia="4.7733e-05 0.000225606 0.000246751 7.6108e-05 -4.61e-10 -2.34439e-07"/>
          <!-- Part link2b -->
          <geom type="mesh" class="visual" pos="0.01 -0 -0.02" quat="0.5 0.5 -0.5 0.5" mesh="link2b" material="link2b_material"/>
          <geom type="mesh" class="collision" pos="0.01 -0 -0.02" quat="0.5 0.5 -0.5 0.5" mesh="link2b" material="link2b_material"/>
          <!-- Part mg996r_2 -->
          <geom type="mesh" class="visual" pos="0.110349 -0.032 -0.043994" quat="0 0 -0 1" mesh="mg996r" material="mg996r_material"/>
          <geom type="mesh" class="collision" pos="0.110349 -0.032 -0.043994" quat="0 0 -0 1" mesh="mg996r" material="mg996r_material"/>
          <!-- Part attach_2 -->
          <geom type="mesh" class="visual" pos="0.110349 -0.032 -0.043494" quat="0 0 -0 1" mesh="attach" material="attach_material"/>
          <geom type="mesh" class="collision" pos="0.110349 -0.032 -0.043494" quat="0 0 -0 1" mesh="attach" material="attach_material"/>
          <!-- Part mg996r_3 -->
          <geom type="mesh" class="visual" pos="-0.0103491 0 -0.043994" quat="1 -0 -0 0" mesh="mg996r" material="mg996r_material"/>
          <geom type="mesh" class="collision" pos="-0.0103491 0 -0.043994" quat="1 -0 -0 0" mesh="mg996r" material="mg996r_material"/>
          <!-- Part attach_3 -->
          <geom type="mesh" class="visual" pos="-0.0103491 0 -0.043494" quat="1 -0 0 0" mesh="attach" material="attach_material"/>
          <geom type="mesh" class="collision" pos="-0.0103491 0 -0.043494" quat="1 -0 0 0" mesh="attach" material="attach_material"/>
          <!-- Link a_v3_link4b -->
          <body name="a_v3_link4b" pos="0.1 -0.032 -0" quat="0 0.707107 -0.707107 0">
            <!-- Joint from a_v3_link2b to a_v3_link4b -->
            <joint axis="0 0 1" name="joint3" type="hinge" range="-3.1415926535891145 6.785683126508957e-13"/>
            <inertial pos="-0.000511853 0.0700615 -0.00734434" mass="0.06872" fullinertia="6.55947e-05 9.44624e-06 6.11744e-05 -9.46598e-07 1.87985e-07 3.60437e-06"/>
            <!-- Part ph_pan_head_screw_m3x0_50_x_6__b32648e3119e9bfb9d9baf1e22451401_7 -->
            <geom type="mesh" class="visual" pos="0 -0 -0.0064" quat="0 0.707107 0.707107 0" mesh="ph_pan_head_screw_m3x0_50_x_6__b32648e3119e9bfb9d9baf1e22451401" material="ph_pan_head_screw_m3x0_50_x_6__b32648e3119e9bfb9d9baf1e22451401_material"/>
            <geom type="mesh" class="collision" pos="0 -0 -0.0064" quat="0 0.707107 0.707107 0" mesh="ph_pan_head_screw_m3x0_50_x_6__b32648e3119e9bfb9d9baf1e22451401" material="ph_pan_head_screw_m3x0_50_x_6__b32648e3119e9bfb9d9baf1e22451401_material"/>
            <!-- Part link4b -->
            <geom type="mesh" class="visual" pos="-0 0.08 -0" quat="0.707107 -0 0.707107 0" mesh="link4b" material="link4b_material"/>
            <geom type="mesh" class="collision" pos="-0 0.08 -0" quat="0.707107 -0 0.707107 0" mesh="link4b" material="link4b_material"/>
            <!-- Part mg996r_straight_3 -->
            <geom type="mesh" class="visual" pos="0 -0 -0.00235" quat="0.707107 0.707107 0 -0" mesh="mg996r_straight" material="mg996r_straight_material"/>
            <geom type="mesh" class="collision" pos="0 -0 -0.00235" quat="0.707107 0.707107 0 -0" mesh="mg996r_straight" material="mg996r_straight_material"/>
            <!-- Part mg996r_4 -->
            <geom type="mesh" class="visual" pos="-0 0.100349 -0.027994" quat="0.707107 -0 -0 -0.707107" mesh="mg996r" material="mg996r_material"/>
            <geom type="mesh" class="collision" pos="-0 0.100349 -0.027994" quat="0.707107 -0 -0 -0.707107" mesh="mg996r" material="mg996r_material"/>
            <!-- Part attach_4 -->
            <geom type="mesh" class="visual" pos="-0 0.100349 -0.027494" quat="0.707107 -0 -0 -0.707107" mesh="attach" material="attach_material"/>
            <geom type="mesh" class="collision" pos="-0 0.100349 -0.027494" quat="0.707107 -0 -0 -0.707107" mesh="attach" material="attach_material"/>
            <!-- Link a_v3_link5b -->
            <body name="a_v3_link5b" pos="-0 0.09 0.016" quat="0 -1 -0 0">
              <!-- Joint from a_v3_link4b to a_v3_link5b -->
              <joint axis="0 0 1" name="joint4" type="hinge" range="-1.5707963267947607 1.5707963267950324"/>
              <inertial pos="0.00932576 -0.0333097 -0.0116357" mass="0.0699648" fullinertia="2.05631e-05 1.42182e-05 2.79017e-05 1.84237e-06 4.26074e-07 -2.79284e-06"/>
              <!-- Part mg996r_straight_4 -->
              <geom type="mesh" class="visual" pos="-0 0 -0.00235" quat="0.707107 0.707107 -0 0" mesh="mg996r_straight" material="mg996r_straight_material"/>
              <geom type="mesh" class="collision" pos="-0 0 -0.00235" quat="0.707107 0.707107 -0 0" mesh="mg996r_straight" material="mg996r_straight_material"/>
              <!-- Part link5b -->
              <geom type="mesh" class="visual" pos="0 -0.042 -0.164" quat="0.707107 -0 0.707107 0" mesh="link5b" material="link5b_material"/>
              <geom type="mesh" class="collision" pos="0 -0.042 -0.164" quat="0.707107 -0 0.707107 0" mesh="link5b" material="link5b_material"/>
              <!-- Part ph_pan_head_screw_m3x0_50_x_6__b32648e3119e9bfb9d9baf1e22451401_8 -->
              <geom type="mesh" class="visual" pos="0 0 -0.0064" quat="0 0.707107 0.707107 0" mesh="ph_pan_head_screw_m3x0_50_x_6__b32648e3119e9bfb9d9baf1e22451401" material="ph_pan_head_screw_m3x0_50_x_6__b32648e3119e9bfb9d9baf1e22451401_material"/>
              <geom type="mesh" class="collision" pos="0 0 -0.0064" quat="0 0.707107 0.707107 0" mesh="ph_pan_head_screw_m3x0_50_x_6__b32648e3119e9bfb9d9baf1e22451401" material="ph_pan_head_screw_m3x0_50_x_6__b32648e3119e9bfb9d9baf1e22451401_material"/>
              <!-- Part mg996r_5 -->
              <geom type="mesh" class="visual" pos="-0.0103491 -0.018006 -0.014" quat="0.707107 0.707107 0 0" mesh="mg996r" material="mg996r_material"/>
              <geom type="mesh" class="collision" pos="-0.0103491 -0.018006 -0.014" quat="0.707107 0.707107 0 0" mesh="mg996r" material="mg996r_material"/>
              <!-- Part attach_5 -->
              <geom type="mesh" class="visual" pos="-0.0103491 -0.018506 -0.014" quat="0.707107 0.707107 0 0" mesh="attach" material="attach_material"/>
              <geom type="mesh" class="collision" pos="-0.0103491 -0.018506 -0.014" quat="0.707107 0.707107 0 0" mesh="attach" material="attach_material"/>
              <!-- Link mg996r_straight -->
              <body name="mg996r_straight" pos="0 -0.062 -0.014" quat="0.5 -0.5 0.5 0.5">
                <!-- Joint from a_v3_link5b to mg996r_straight -->
                <joint axis="0 0 1" name="joint5" type="hinge" range="-1.5707963267948815 1.5707963267949117"/>
                <inertial pos="0 -0 -0.000657539" mass="0.000866123" fullinertia="6.6112e-08 7.262e-09 7.0424e-08 0 -0 -0"/>
                <!-- Part mg996r_straight_5 -->
                <geom type="mesh" class="visual" pos="0 0 -0.00235" quat="0.707107 0.707107 0 0" mesh="mg996r_straight" material="mg996r_straight_material"/>
                <geom type="mesh" class="collision" pos="0 0 -0.00235" quat="0.707107 0.707107 0 0" mesh="mg996r_straight" material="mg996r_straight_material"/>
              </body>
            </body>
          </body>
        </body>
      </body>
    </body>
  </worldbody>
  <asset>
    <mesh file="lqfp_32_5x5mm_p05mm.stl"/>
    <mesh file="mg996r.stl"/>
    <mesh file="attach.stl"/>
    <mesh file="ph_pan_head_screw_m3x0_50_x_10__f9471002c7d2be787504e53f034b0545.stl"/>
    <mesh file="pinheader_1x15_p254mm_vertical.stl"/>
    <mesh file="link1_1b.stl"/>
    <mesh file="ph_pan_head_screw_m3x0_50_x_6__b32648e3119e9bfb9d9baf1e22451401.stl"/>
    <mesh file="esp32_30pin_pcb.stl"/>
    <mesh file="link5b.stl"/>
    <mesh file="usb_micro_b_molex_47346_0001.stl"/>
    <mesh file="link2b.stl"/>
    <mesh file="pinheader_1x15_p254mm_vertical_1.stl"/>
    <mesh file="pca9685_generic.stl"/>
    <mesh file="base.stl"/>
    <mesh file="link4b.stl"/>
    <mesh file="lqfp_52_14x14mm_p1mm.stl"/>
    <mesh file="link1_1.stl"/>
    <mesh file="mg996r_straight.stl"/>
    <material name="ph_pan_head_screw_m3x0_50_x_6__b32648e3119e9bfb9d9baf1e22451401_material" rgba="0.603922 0.647059 0.686275 1"/>
    <material name="base_material" rgba="0.972549 0.529412 0.00392157 1"/>
    <material name="pca9685_generic_material" rgba="0.231373 0.380392 0.705882 1"/>
    <material name="pinheader_1x15_p254mm_vertical_material" rgba="0.858824 0.737255 0.494118 1"/>
    <material name="lqfp_52_14x14mm_p1mm_material" rgba="0.823529 0.819608 0.780392 1"/>
    <material name="usb_micro_b_molex_47346_0001_material" rgba="0.823529 0.819608 0.780392 1"/>
    <material name="esp32_30pin_pcb_material" rgba="0.313725 0.486275 0.411765 1"/>
    <material name="lqfp_32_5x5mm_p05mm_material" rgba="0.823529 0.819608 0.780392 1"/>
    <material name="pinheader_1x15_p254mm_vertical_1_material" rgba="0.858824 0.737255 0.494118 1"/>
    <material name="mg996r_material" rgba="0.301961 0.301961 0.301961 1"/>
    <material name="attach_material" rgba="0.796078 0.823529 0.937255 1"/>
    <material name="link1_1_material" rgba="0.972549 0.529412 0.00392157 1"/>
    <material name="ph_pan_head_screw_m3x0_50_x_10__f9471002c7d2be787504e53f034b0545_material" rgba="0.603922 0.647059 0.686275 1"/>
    <material name="mg996r_straight_material" rgba="0.439216 0.47451 0.501961 1"/>
    <material name="link1_1b_material" rgba="0.647059 0.647059 0.647059 1"/>
    <material name="link2b_material" rgba="0.972549 0.529412 0.00392157 1"/>
    <material name="link4b_material" rgba="0.972549 0.529412 0.00392157 1"/>
    <material name="link5b_material" rgba="0.972549 0.529412 0.00392157 1"/>
  </asset>
  <actuator>
    <position class="morris_6dof_mujoco" name="joint1" joint="joint1" inheritrange="1"/>
    <position class="morris_6dof_mujoco" name="joint2" joint="joint2" inheritrange="1"/>
    <position class="morris_6dof_mujoco" name="joint3" joint="joint3" inheritrange="1"/>
    <position class="morris_6dof_mujoco" name="joint4" joint="joint4" inheritrange="1"/>
    <position class="morris_6dof_mujoco" name="joint5" joint="joint5" inheritrange="1"/>
  </actuator>
  <equality/>
</mujoco>
